/usr/local/src/conda/python-3.12.0/Include/internal/pycore_pystate.h: 82 - 82
--------------------------------------------------------------------------------

/usr/local/src/conda/python-3.12.0/Include/internal/pycore_call.h: 44 - 44
--------------------------------------------------------------------------------

/usr/local/src/conda/python-3.12.0/Include/internal/pycore_call.h: 54 - 54
--------------------------------------------------------------------------------

/usr/local/src/conda/python-3.12.0/Include/internal/pycore_call.h: 88 - 93
--------------------------------------------------------------------------------

/usr/local/src/conda/python-3.12.0/Objects/call.c: 28 - 29
--------------------------------------------------------------------------------

/usr/local/src/conda/python-3.12.0/Objects/call.c: 398 - 398
--------------------------------------------------------------------------------

/usr/local/src/conda/python-3.12.0/Python/errors.c: 33 - 34
--------------------------------------------------------------------------------

/usr/local/src/conda/python-3.12.0/Python/errors.c: 43 - 47
--------------------------------------------------------------------------------

/usr/local/src/conda/python-3.12.0/Python/errors.c: 53 - 54
--------------------------------------------------------------------------------

/usr/local/src/conda/python-3.12.0/Python/errors.c: 90 - 90
--------------------------------------------------------------------------------

/usr/local/src/conda/python-3.12.0/Python/errors.c: 104 - 104
--------------------------------------------------------------------------------

/usr/local/src/conda/python-3.12.0/Python/errors.c: 127 - 131
--------------------------------------------------------------------------------

/usr/local/src/conda/python-3.12.0/Python/errors.c: 141 - 142
--------------------------------------------------------------------------------

/usr/local/src/conda/python-3.12.0/Python/errors.c: 162 - 167
--------------------------------------------------------------------------------

/usr/local/src/conda/python-3.12.0/Python/errors.c: 176 - 183
--------------------------------------------------------------------------------

/usr/local/src/conda/python-3.12.0/Python/errors.c: 209 - 209
--------------------------------------------------------------------------------

/usr/local/src/conda/python-3.12.0/Python/errors.c: 218 - 238
--------------------------------------------------------------------------------

/usr/local/src/conda/python-3.12.0/Python/errors.c: 247 - 250
--------------------------------------------------------------------------------

/usr/local/src/conda/python-3.12.0/Python/errors.c: 490 - 491
--------------------------------------------------------------------------------

/usr/local/src/conda/python-3.12.0/Include/internal/pycore_pyerrors.h: 23 - 23
--------------------------------------------------------------------------------

/usr/local/src/conda/python-3.12.0/Include/object.h: 220 - 220
--------------------------------------------------------------------------------

/usr/local/src/conda/python-3.12.0/Include/object.h: 243 - 243
--------------------------------------------------------------------------------

/usr/local/src/conda/python-3.12.0/Include/object.h: 644 - 647
--------------------------------------------------------------------------------

/usr/local/src/conda/python-3.12.0/Include/object.h: 701 - 706
--------------------------------------------------------------------------------

/usr/local/src/conda/python-3.12.0/Include/object.h: 788 - 788
--------------------------------------------------------------------------------

/usr/local/src/conda/python-3.12.0/Include/object.h: 798 - 798
--------------------------------------------------------------------------------

/usr/local/src/conda/python-3.12.0/Include/object.h: 967 - 967
--------------------------------------------------------------------------------

/usr/local/src/conda/python-3.12.0/Objects/exceptions.c: 380 - 380
--------------------------------------------------------------------------------

/usr/local/src/conda/python-3.12.0/Objects/exceptions.c: 417 - 418
--------------------------------------------------------------------------------

