/usr/local/src/conda/python-3.9.19/Include/internal/pycore_pyerrors.h: 14 - 14
--------------------------------------------------------------------------------

/usr/local/src/conda/python-3.9.19/Objects/call.c: 35 - 39
--------------------------------------------------------------------------------

/usr/local/src/conda/python-3.9.19/Objects/call.c: 57 - 57
--------------------------------------------------------------------------------

/usr/local/src/conda/python-3.9.19/Objects/call.c: 79 - 79
--------------------------------------------------------------------------------

