/usr/local/src/conda/python-3.9.19/Include/internal/pycore_pyerrors.h: 14 - 14
--------------------------------------------------------------------------------

/usr/local/src/conda/python-3.9.19/Objects/call.c: 38 - 39
--------------------------------------------------------------------------------

/usr/local/src/conda/python-3.9.19/Objects/call.c: 57 - 57
--------------------------------------------------------------------------------

/usr/local/src/conda/python-3.9.19/Objects/call.c: 134 - 134
--------------------------------------------------------------------------------

/usr/local/src/conda/python-3.9.19/Objects/call.c: 380 - 387
--------------------------------------------------------------------------------

/usr/local/src/conda/python-3.9.19/Objects/call.c: 396 - 396
--------------------------------------------------------------------------------

